Workbook

Sheet Cover
A1: Project | B1: Apple 3-Statement Financial Model
A2: Company | B2: Apple Inc.
A3: Ticker | B3: AAPL
A4: Historical Years | B4: 2022A–2024A
A5: Forecast Years | B5: 2025E–2029E
A6: currency | B6: USD millions
A7: source | B7: Apple 2024 Form 10-K
A8: created by | B8: Divya Lachman
A9: purpose | B9: Practice financial modeling, forecasting, and 3-statement analysis

Sheet Historical Financials 
B1: 2022A | C1: 2023A | D1: 2024A | E1: Source
B2: $ | C2: $ | D2: $
A3: Income Statement:
A4: Products net sales | B4: 316199 | C4: 298085 | D4: 294866 | E4: Apple FY2024 Form 10-K, Income Statement
A5: Services net sales | B5: 78129 | C5: 85200 | D5: 96169 | E5: Apple FY2024 Form 10-K, Income Statement
A6: Total net sales | B6: 394328 | C6: 383285 | D6: 391035 | E6: Apple FY2024 Form 10-K, Income Statement
A7: Products cost of sales | B7: 201471 | C7: 189282 | D7: 185233 | E7: Apple FY2024 Form 10-K, Income Statement
A8: Services cost of sales | B8: 22075 | C8: 24855 | D8: 25119 | E8: Apple FY2024 Form 10-K, Income Statement
A9: Total cost of sales | B9: 223546 | C9: 214137 | D9: 210352 | E9: Apple FY2024 Form 10-K, Income Statement
A10: Gross margin | B10: 170782 | C10: 169148 | D10: 180683 | E10: Apple FY2024 Form 10-K, Income Statement
A11: Research and development | B11: 26251 | C11: 29915 | D11: 31370 | E11: Apple FY2024 Form 10-K, Income Statement
A12: Selling, general and administrative | B12: 25094 | C12: 24932 | D12: 26097 | E12: Apple FY2024 Form 10-K, Income Statement
A13: Total operating expenses | B13: 51345 | C13: 54847 | D13: 57467 | E13: Apple FY2024 Form 10-K, Income Statement
A14: Operating income | B14: 119437 | C14: 114301 | D14: 123216 | E14: Apple FY2024 Form 10-K, Income Statement
A15: Other income/(expense), net | B15: -334 | C15: -565 | D15: 269 | E15: Apple FY2024 Form 10-K, Income Statement
... A22: Diluted shares | B22: 16325819 | C22: 15812547 | D22: 15408095 | E22: Apple FY2024 Form 10-K, Income Statement
A24: Balance Sheet:
A25: Cash and cash equivalents | C25: 29965 | D25: 29943 | E25: Apple FY2024 Form 10-K, Balance Sheet
A26: Marketable securities - current | C26: 31590 | D26: 35228 | E26: Apple FY2024 Form 10-K, Balance Sheet
A27: Accounts receivable, net | C27: 29508 | D27: 33410 | E27: Apple FY2024 Form 10-K, Balance Sheet
A28: Vendor non-trade receivables | C28: 31477 | D28: 32833 | E28: Apple FY2024 Form 10-K, Balance Sheet
A29: Inventories | C29: 6331 | D29: 7286 | E29: Apple FY2024 Form 10-K, Balance Sheet
A30: Other current assets | C30: 14695 | D30: 14287 | E30: Apple FY2024 Form 10-K, Balance Sheet
A31: Total current assets | C31: 143566 | D31: 152987 | E31: Apple FY2024 Form 10-K, Balance Sheet
A32: Marketable securities - non-current | C32: 100544 | D32: 91479 | E32: Apple FY2024 Form 10-K, Balance Sheet
A33: Property, plant and equipment, net | C33: 43715 | D33: 45680 | E33: Apple FY2024 Form 10-K, Balance Sheet
A34: Other non-current assets | C34: 64758 | D34: 74834 | E34: Apple FY2024 Form 10-K, Balance Sheet
A35: Total non-current assets | C35: 209017 | D35: 211993 | E35: Apple FY2024 Form 10-K, Balance Sheet
A36: Total assets | C36: 352583 | D36: 364980 | E36: Apple FY2024 Form 10-K, Balance Sheet
... A53: Total liabilities and shareholders’ equity | C53: 352583 | D53: 364980 | E53: Apple FY2024 Form 10-K, Balance Sheet
A55: Cash Flow
A56: Cash at beginning of year | B56: 35929 | C56: 24977 | D56: 30737 | E56: Apple FY2024 Form 10-K, Cash Flow Statement
A57: Net income | B57: 99803 | C57: 96995 | D57: 93736 | E57: Apple FY2024 Form 10-K, Cash Flow Statement
A58: Depreciation and amortization | B58: 11104 | C58: 11519 | D58: 11445 | E58: Apple FY2024 Form 10-K, Cash Flow Statement
A59: Share-based compensation expense | B59: 9038 | C59: 10833 | D59: 11688 | E59: Apple FY2024 Form 10-K, Cash Flow Statement
A60: Other adjustments | B60: 1006 | C60: -2227 | D60: -2266 | E60: Apple FY2024 Form 10-K, Cash Flow Statement
A61: Accounts receivable change | B61: -1823 | C61: -1688 | D61: -3788 | E61: Apple FY2024 Form 10-K, Cash Flow Statement
A62: Vendor non-trade receivables change | B62: -7520 | C62: 1271 | D62: -1356 | E62: Apple FY2024 Form 10-K, Cash Flow Statement
A63: Inventories change | B63: 1484 | C63: -1618 | D63: -1046 | E63: Apple FY2024 Form 10-K, Cash Flow Statement
A64: Other current and non-current assets change | B64: -6499 | C64: -5684 | D64: -11731 | E64: Apple FY2024 Form 10-K, Cash Flow Statement
...

Sheet Assumptions
B1: 2022A | C1: 2023A | D1: 2024A | E1: AVERAGE | F1: 2025E | G1: 2026E | H1: 2027E | I1: 2028E | J1: 2029E
A2: Assumptions
A4: Income Statement Assumptions
A5: Revenue growth % | C5: =('Historical Financials '!C6/'Historical Financials '!B6)-1 -> -0.028004605 | D5: =('Historical Financials '!D6/'Historical Financials '!C6)-1 -> 0.020219941 | E5: =AVERAGE(B5:D5) -> -0.0038923323 | F5: =E5 -> -0.0038923323 | G5: =F5 -> -0.0038923323 | H5: =G5 -> -0.0038923323 | I5: =H5 -> -0.0038923323 | J5: =I5 -> -0.0038923323
A6: Gross margin % | B6: ='Historical Financials '!B10/'Historical Financials '!B6 -> 0.43309631 | C6: ='Historical Financials '!C10/'Historical Financials '!C6 -> 0.4413113 | D6: ='Historical Financials '!D10/'Historical Financials '!D6 -> 0.4620635 | E6: =AVERAGE(B6:D6) -> 0.44549037 | F6: =E6 -> 0.44549037 | G6: =F6 -> 0.44549037 | H6: =G6 -> 0.44549037 | I6: =H6 -> 0.44549037 | J6: =I6 -> 0.44549037
A7: R&D as % of sales | B7: ='Historical Financials '!B11/'Historical Financials '!B6 -> 0.066571484 | C7: ='Historical Financials '!C11/'Historical Financials '!C6 -> 0.078048971 | D7: ='Historical Financials '!D11/'Historical Financials '!D6 -> 0.080222998 | E7: =AVERAGE(B7:D7) -> 0.074947818 | F7: =E7 -> 0.074947818 | G7: =F7 -> 0.074947818 | H7: =G7 -> 0.074947818 | I7: =H7 -> 0.074947818 | J7: =I7 -> 0.074947818
A8: SG&A as % of sales | B8: ='Historical Financials '!B12/'Historical Financials '!B6 -> 0.063637378 | C8: ='Historical Financials '!C12/'Historical Financials '!C6 -> 0.065048202 | D8: ='Historical Financials '!D12/'Historical Financials '!D6 -> 0.066738272 | E8: =AVERAGE(B8:D8) -> 0.065141284 | F8: =E8 -> 0.065141284 | G8: =F8 -> 0.065141284 | H8: =G8 -> 0.065141284 | I8: =H8 -> 0.065141284 | J8: =I8 -> 0.065141284
A9: Other income / expense as % of sales | B9: ='Historical Financials '!B15/'Historical Financials '!B6 -> -0.00084701061 | C9: ='Historical Financials '!C15/'Historical Financials '!C6 -> -0.0014740989 | D9: ='Historical Financials '!D15/'Historical Financials '!D6 -> 0.00068791796 | E9: =AVERAGE(B9:D9) -> -0.00054439719 | F9: =E9 -> -0.00054439719 | G9: =F9 -> -0.00054439719 | H9: =G9 -> -0.00054439719 | I9: =H9 -> -0.00054439719 | J9: =I9 -> -0.00054439719
A10: Tax rate % | B10: ='Historical Financials '!B17/'Historical Financials '!B16 -> 0.16204462 | C10: ='Historical Financials '!C17/'Historical Financials '!C16 -> 0.14719174 | D10: ='Historical Financials '!D17/'Historical Financials '!D16 -> 0.24091185 | E10: =AVERAGE(B10:D10) -> 0.18338274 | F10: =E10 -> 0.18338274 | G10: =F10 -> 0.18338274 | H10: =G10 -> 0.18338274 | I10: =H10 -> 0.18338274 | J10: =I10 -> 0.18338274
A11: Net income margin | B11: ='Historical Financials '!B18/'Historical Financials '!B6 -> 0.25309641 | C11: ='Historical Financials '!C18/'Historical Financials '!C6 -> 0.25306234 | D11: ='Historical Financials '!D18/'Historical Financials '!D6 -> 0.23971256 | E11: =AVERAGE(B11:D11) -> 0.24862377 | F11: =E11 -> 0.24862377 | G11: =F11 -> 0.24862377 | H11: =G11 -> 0.24862377 | I11: =H11 -> 0.24862377 | J11: =I11 -> 0.24862377
A13: Balance Sheet Assumptions
A14: Accounts receivable as % of sales | C14: ='Historical Financials '!C27/'Historical Financials '!C6 -> 0.076987098 | D14: ='Historical Financials '!D27/'Historical Financials '!D6 -> 0.085439922 | E14: =AVERAGE(B14:D14) -> 0.08121351 | F14: =AVERAGE(C14:E14) -> 0.08121351 | G14: =AVERAGE(D14:F14) -> 0.082622314 | H14: =AVERAGE(E14:G14) -> 0.081683112 | I14: =AVERAGE(F14:H14) -> 0.081839645 | J14: =AVERAGE(G14:I14) -> 0.082048357
A15: Inventories as % of sales | C15: ='Historical Financials '!C29/'Historical Financials '!C6 -> 0.016517735 | D15: ='Historical Financials '!D29/'Historical Financials '!D6 -> 0.018632603 | E15: =AVERAGE(B15:D15) -> 0.017575169 | F15: =AVERAGE(C15:E15) -> 0.017575169 | G15: =AVERAGE(D15:F15) -> 0.017927647 | H15: =AVERAGE(E15:G15) -> 0.017692662 | I15: =AVERAGE(F15:H15) -> 0.017731826 | J15: =AVERAGE(G15:I15) -> 0.017784045
A16: Other current assets as % of sales | C16: ='Historical Financials '!C30/'Historical Financials '!C6 -> 0.038339617 | D16: ='Historical Financials '!D30/'Historical Financials '!D6 -> 0.036536371 | E16: =AVERAGE(B16:D16) -> 0.037437994 | F16: =AVERAGE(C16:E16) -> 0.037437994 | G16: =AVERAGE(D16:F16) -> 0.037137453 | H16: =AVERAGE(E16:G16) -> 0.037337814 | I16: =AVERAGE(F16:H16) -> 0.03730442 | J16: =AVERAGE(G16:I16) -> 0.037259896
A17: Accounts payable as % of cost of sales | C17: ='Historical Financials '!C38/'Historical Financials '!C9 -> 0.29238758 | D17: ='Historical Financials '!D38/'Historical Financials '!D9 -> 0.32783144 | E17: =AVERAGE(B17:D17) -> 0.31010951 | F17: =AVERAGE(C17:E17) -> 0.31010951 | G17: =AVERAGE(D17:F17) -> 0.31601682 | H17: =AVERAGE(E17:G17) -> 0.31207862 | I17: =AVERAGE(F17:H17) -> 0.31273499 | J17: =AVERAGE(G17:I17) -> 0.31361014
A18: Other current liabilities as % of sales | C18: ='Historical Financials '!C39/'Historical Financials '!C6 -> 0.15348631 | D18: ='Historical Financials '!D39/'Historical Financials '!D6 -> 0.20024806 | E18: =AVERAGE(B18:D18) -> 0.17686718 | F18: =AVERAGE(C18:E18) -> 0.17686718 | G18: =AVERAGE(D18:F18) -> 0.18466081 | H18: =AVERAGE(E18:G18) -> 0.17946506 | I18: =AVERAGE(F18:H18) -> 0.18033102 | J18: =AVERAGE(G18:I18) -> 0.18148563
A19: Deferred revenue as % of sales | C19: ='Historical Financials '!C40/'Historical Financials '!C6 -> 0.021031347 | D19: ='Historical Financials '!D40/'Historical Financials '!D6 -> 0.021095298 | E19: =AVERAGE(B19:D19) -> 0.021063323 | F19: =AVERAGE(C19:E19) -> 0.021063323 | G19: =AVERAGE(D19:F19) -> 0.021073981 | H19: =AVERAGE(E19:G19) -> 0.021066876 | I19: =AVERAGE(F19:H19) -> 0.02106806 | J19: =AVERAGE(G19:I19) -> 0.021069639
A21: Cash Flow Assumptions
A22: Depreciation & amortization as % of sales | B22: ='Historical Financials '!B58/'Historical Financials '!B6 -> 0.028159299 | C22: ='Historical Financials '!C58/'Historical Financials '!C6 -> 0.030053355 | D22: ='Historical Financials '!D58/'Historical Financials '!D6 -> 0.02926848 | E22: =AVERAGE(B22:D22) -> 0.029160378 | F22: =AVERAGE(C22:E22) -> 0.029494071 | G22: =AVERAGE(D22:F22) -> 0.029307643 | H22: =AVERAGE(E22:G22) -> 0.029320697 | I22: =AVERAGE(F22:H22) -> 0.029374137 | J22: =AVERAGE(G22:I22) -> 0.029334159
A23: Share-based compensation as % of sales | B23: ='Historical Financials '!B59/'Historical Financials '!B6 -> 0.022920006 | C23: ='Historical Financials '!C59/'Historical Financials '!C6 -> 0.028263564 | D23: ='Historical Financials '!D59/'Historical Financials '!D6 -> 0.029889908 | E23: =AVERAGE(B23:D23) -> 0.027024492 | F23: =AVERAGE(C23:E23) -> 0.028392655 | G23: =AVERAGE(D23:F23) -> 0.028435685 | H23: =AVERAGE(E23:G23) -> 0.027950944 | I23: =AVERAGE(F23:H23) -> 0.028259761 | J23: =AVERAGE(G23:I23) -> 0.028215463
A24: CapEx as % of sales | B24: =ABS('Historical Financials '!B71/'Historical Financials '!B6) -> 0.027155059 | C24: =ABS('Historical Financials '!C71/'Historical Financials '!C6) -> 0.028592301 | D24: =ABS('Historical Financials '!D71/'Historical Financials '!D6) -> 0.024158963 | E24: =AVERAGE(B24:D24) -> 0.026635441 | F24: =AVERAGE(C24:E24) -> 0.026462235 | G24: =AVERAGE(D24:F24) -> 0.025752213 | H24: =AVERAGE(E24:G24) -> 0.026283296 | I24: =AVERAGE(F24:H24) -> 0.026165915 | J24: =AVERAGE(G24:I24) -> 0.026067141
A25: Dividends as % of net income | B25: =ABS('Historical Financials '!B75/'Historical Financials '!B18) -> 0.14870294 | C25: =ABS('Historical Financials '!C75/'Historical Financials '!C18) -> 0.15490489 | D25: =ABS('Historical Financials '!D75/'Historical Financials '!D18) -> 0.16252027 | E25: =AVERAGE(B25:D25) -> 0.15537604 | F25: =AVERAGE(C25:E25) -> 0.1576004 | G25: =AVERAGE(D25:F25) -> 0.1584989 | H25: =AVERAGE(E25:G25) -> 0.15715845 | I25: =AVERAGE(F25:H25) -> 0.15775258 | J25: =AVERAGE(G25:I25) -> 0.15780331
A26: Share repurchases as % of sales | B26: =ABS('Historical Financials '!B76/'Historical Financials '!B6) -> 0.22671989 | C26: =ABS('Historical Financials '!C76/'Historical Financials '!C6) -> 0.20232986 | D26: =ABS('Historical Financials '!D76/'Historical Financials '!D6) -> 0.24281458 | E26: =AVERAGE(B26:D26) -> 0.22395478 | F26: =AVERAGE(C26:E26) -> 0.22303307 | G26: =AVERAGE(D26:F26) -> 0.22993414 | H26: =AVERAGE(E26:G26) -> 0.22564066 | I26: =AVERAGE(F26:H26) -> 0.22620263 | J26: =AVERAGE(G26:I26) -> 0.22725914
A28: Debt / Interest Assumptions
A29: Current debt | C29: ='Historical Financials '!C41+'Historical Financials '!C42 -> 15807 | D29: ='Historical Financials '!D41+'Historical Financials '!D42 -> 20879
A30: Non-current debt | C30: ='Historical Financials '!C44 -> 95281 | D30: ='Historical Financials '!D44 -> 85750
A31: Total debt | C31: =SUM(C29:C30) -> 111088 | D31: =SUM(D29:D30) -> 106629

Sheet Income Statement
A1: Apple Inc.
A2: Consolidated Statement of Operations
A3: Fiscal Years 2022A–2029E
A4: USD in millions, except per share amounts
B6: 2022A | C6: 2023A | D6: 2024A | E6: 2025E | F6: 2026E | G6: 2027E | H6: 2028E | I6: 2029E
A7: Net sales:
A8: Products net sales | B8: ='Historical Financials '!B4 -> 316199 | C8: ='Historical Financials '!C4 -> 298085 | D8: ='Historical Financials '!D4 -> 294866 | E8: =E10*(D8/D10) -> 293718.28 | F8: =F10*(E8/E10) -> 292575.03 | G8: =G10*(F8/F10) -> 291436.24 | H8: =H10*(G8/G10) -> 290301.87 | I8: =I10*(H8/H10) -> 289171.92
A9: Services net sales | B9: ='Historical Financials '!B5 -> 78129 | C9: ='Historical Financials '!C5 -> 85200 | D9: ='Historical Financials '!D5 -> 96169 | E9: =E10*(D9/D10) -> 95794.678 | F9: =F10*(E9/E10) -> 95421.814 | G9: =G10*(F9/F10) -> 95050.4 | H9: =H10*(G9/G10) -> 94680.432 | I9: =I10*(H9/H10) -> 94311.905
A10: Total net sales | B10: ='Historical Financials '!B6 -> 394328 | C10: ='Historical Financials '!C6 -> 383285 | D10: ='Historical Financials '!D6 -> 391035 | E10: =D10*(1+Assumptions!F5) -> 389512.96 | F10: =E10*(1+Assumptions!G5) -> 387996.85 | G10: =F10*(1+Assumptions!H5) -> 386486.64 | H10: =G10*(1+Assumptions!I5) -> 384982.3 | I10: =H10*(1+Assumptions!J5) -> 383483.82
A12: Cost of sales:
A13: Products cost of sales | B13: ='Historical Financials '!B7 -> 201471 | C13: ='Historical Financials '!C7 -> 189282 | D13: ='Historical Financials '!D7 -> 185233 | E13: =E15*(D13/D15) -> 190196.59 | F13: =F15*(E13/E15) -> 189456.28 | G13: =G15*(F13/F15) -> 188718.85 | H13: =H15*(G13/G15) -> 187984.3 | I13: =I15*(H13/H15) -> 187252.6
A14: Services cost of sales | B14: ='Historical Financials '!B8 -> 22075 | C14: ='Historical Financials '!C8 -> 24855 | D14: ='Historical Financials '!D8 -> 25119 | E14: =E15*(D14/D15) -> 25792.1 | F14: =F15*(E14/E15) -> 25691.709 | G14: =G15*(F14/F15) -> 25591.708 | H14: =H15*(G14/G15) -> 25492.097 | I14: =I15*(H14/H15) -> 25392.873
A15: Total cost of sales | B15: ='Historical Financials '!B9 -> 223546 | C15: ='Historical Financials '!C9 -> 214137 | D15: ='Historical Financials '!D9 -> 210352 | E15: =E10-E17 -> 215988.69 | F15: =F10-F17 -> 215147.99 | G15: =G10-G17 -> 214310.56 | H15: =H10-H17 -> 213476.39 | I15: =I10-I17 -> 212645.47
A17: Gross margin | B17: ='Historical Financials '!B10 -> 170782 | C17: ='Historical Financials '!C10 -> 169148 | D17: ='Historical Financials '!D10 -> 180683 | E17: =E10*Assumptions!F6 -> 173524.27 | F17: =F10*Assumptions!G6 -> 172848.86 | G17: =G10*Assumptions!H6 -> 172176.07 | H17: =H10*Assumptions!I6 -> 171505.91 | I17: =I10*Assumptions!J6 -> 170838.35
A19: Operating expenses:
A20: Research and development | B20: ='Historical Financials '!B11 -> 26251 | C20: ='Historical Financials '!C11 -> 29915 | D20: ='Historical Financials '!D11 -> 31370 | E20: =E10*Assumptions!F7 -> 29193.146 | F20: =F10*Assumptions!G7 -> 29079.517 | G20: =G10*Assumptions!H7 -> 28966.33 | H20: =H10*Assumptions!I7 -> 28853.583 | I20: =I10*Assumptions!J7 -> 28741.276
A21: Selling, general and administrative | B21: ='Historical Financials '!B12 -> 25094 | C21: ='Historical Financials '!C12 -> 24932 | D21: ='Historical Financials '!D12 -> 26097 | E21: =E10*Assumptions!F8 -> 25373.374 | F21: =F10*Assumptions!G8 -> 25274.613 | G21: =G10*Assumptions!H8 -> 25176.236 | H21: =H10*Assumptions!I8 -> 25078.241 | I21: =I10*Assumptions!J8 -> 24980.628
A22: Total operating expenses | B22: ='Historical Financials '!B13 -> 51345 | C22: ='Historical Financials '!C13 -> 54847 | D22: ='Historical Financials '!D13 -> 57467 | E22: =SUM(E20:E21) -> 54566.521 | F22: =SUM(F20:F21) -> 54354.13 | G22: =SUM(G20:G21) -> 54142.565 | H22: =SUM(H20:H21) -> 53931.825 | I22: =SUM(I20:I21) -> 53721.904
A24: Operating income | B24: ='Historical Financials '!B14 -> 119437 | C24: ='Historical Financials '!C14 -> 114301 | D24: ='Historical Financials '!D14 -> 123216 | E24: =E17-E22 -> 118957.75 | F24: =F17-F22 -> 118494.73 | G24: =G17-G22 -> 118033.51 | H24: =H17-H22 -> 117574.08 | I24: =I17-I22 -> 117116.44
A25: Other income/(expense), net | B25: ='Historical Financials '!B15 -> -334 | C25: ='Historical Financials '!C15 -> -565 | D25: ='Historical Financials '!D15 -> 269 | E25: =E10*Assumptions!F9 -> -212.04976 | F25: =F10*Assumptions!G9 -> -211.22439 | G25: =G10*Assumptions!H9 -> -210.40224 | H25: =H10*Assumptions!I9 -> -209.58328 | I25: =I10*Assumptions!J9 -> -208.76751
A26: Income before provision for income taxes | B26: ='Historical Financials '!B16 -> 119103 | C26: ='Historical Financials '!C16 -> 113736 | D26: ='Historical Financials '!D16 -> 123485 | E26: =SUM(E24:E25) -> 118745.7 | F26: =SUM(F24:F25) -> 118283.5 | G26: =SUM(G24:G25) -> 117823.11 | H26: =SUM(H24:H25) -> 117364.5 | I26: =SUM(I24:I25) -> 116907.68
A27: Provision for income taxes | B27: ='Historical Financials '!B17 -> 19300 | C27: ='Historical Financials '!C17 -> 16741 | D27: ='Historical Financials '!D17 -> 29749 | E27: =E26*Assumptions!F10 -> 21775.912 | F27: =F26*Assumptions!G10 -> 21691.153 | G27: =G26*Assumptions!H10 -> 21606.723 | H27: =H26*Assumptions!I10 -> 21522.623 | I27: =I26*Assumptions!J10 -> 21438.85
A28: Net income | B28: ='Historical Financials '!B18 -> 99803 | C28: ='Historical Financials '!C18 -> 96995 | D28: ='Historical Financials '!D18 -> 93736 | E28: =E26-E27 -> 96969.79 | F28: =F26-F27 -> 96592.351 | G28: =G26-G27 -> 96216.382 | H28: =H26-H27 -> 95841.876 | I28: =I26-I27 -> 95468.827
A30: Basic EPS | B30: ='Historical Financials '!B19 -> 6.15 | C30: ='Historical Financials '!C19 -> 6.16 | D30: ='Historical Financials '!D19 -> 6.11 | E30: =E28*1000/E32 -> 6.3198098 | F30: =F28*1000/F32 -> 6.295211 | G30: =G28*1000/G32 -> 6.2707079 | H30: =H28*1000/H32 -> 6.2463002 | I30: =I28*1000/I32 -> 6.2219876
A31: Diluted EPS | B31: ='Historical Financials '!B20 -> 6.11 | C31: ='Historical Financials '!C20 -> 6.13 | D31: ='Historical Financials '!D20 -> 6.08 | E31: =E28*1000/E33 -> 6.2934315 | F31: =F28*1000/F33 -> 6.2689353 | G31: =G28*1000/G33 -> 6.2445346 | H31: =H28*1000/H33 -> 6.2202288 | I31: =I28*1000/I33 -> 6.1960176
A32: Basic shares | B32: ='Historical Financials '!B21 -> 16215963 | C32: ='Historical Financials '!C21 -> 15744231 | D32: ='Historical Financials '!D21 -> 15343783 | E32: =D32 -> 15343783 | F32: =E32 -> 15343783 | G32: =F32 -> 15343783 | H32: =G32 -> 15343783 | I32: =H32 -> 15343783
A33: Diluted shares | B33: ='Historical Financials '!B22 -> 16325819 | C33: ='Historical Financials '!C22 -> 15812547 | D33: ='Historical Financials '!D22 -> 15408095 | E33: =D33 -> 15408095 | F33: =E33 -> 15408095 | G33: =F33 -> 15408095 | H33: =G33 -> 15408095 | I33: =H33 -> 15408095

Sheet Balance Sheet
A1: Apple Inc.
A2: Consolidated Balance Sheets
A3: Fiscal Years 2023A–2029E
A4: USD in millions
B6: 2022A | C6: 2023A | D6: 2024A | E6: 2025E | F6: 2026E | G6: 2027E | H6: 2028E | I6: 2029E
A7: Balance Sheet
A8: Assets:
A9: Cash and cash equivalents | C9: ='Historical Financials '!C25 -> 29965 | D9: ='Historical Financials '!D25 -> 29943 | E9: ='Cash Flow'!B31 -> 27480.877 | F9: ='Cash Flow'!C31 -> 35340.136 | G9: ='Cash Flow'!D31 -> 38358.912 | H9: ='Cash Flow'!E31 -> 44167.232 | I9: ='Cash Flow'!F31 -> 49683.524
A10: Marketable securities - current | C10: ='Historical Financials '!C26 -> 31590 | D10: ='Historical Financials '!D26 -> 35228 | E10: =D10 -> 35228 | F10: =E10 -> 35228 | G10: =F10 -> 35228 | H10: =G10 -> 35228 | I10: =H10 -> 35228
A11: Accounts receivable, net | C11: ='Historical Financials '!C27 -> 29508 | D11: ='Historical Financials '!D27 -> 33410 | E11: ='Income Statement'!E10*Assumptions!F14 -> 31633.715 | F11: ='Income Statement'!F10*Assumptions!G14 -> 32057.198 | G11: ='Income Statement'!G10*Assumptions!H14 -> 31569.431 | H11: ='Income Statement'!H10*Assumptions!I14 -> 31506.815 | I11: ='Income Statement'!I10*Assumptions!J14 -> 31464.218
A12: Vendor non-trade receivables | C12: ='Historical Financials '!C28 -> 31477 | D12: ='Historical Financials '!D28 -> 32833 | E12: =D12 -> 32833 | F12: =E12 -> 32833 | G12: =F12 -> 32833 | H12: =G12 -> 32833 | I12: =H12 -> 32833
A13: Inventories | C13: ='Historical Financials '!C29 -> 6331 | D13: ='Historical Financials '!D29 -> 7286 | E13: ='Income Statement'!E10*Assumptions!F15 -> 6845.7561 | F13: ='Income Statement'!F10*Assumptions!G15 -> 6955.8706 | G13: ='Income Statement'!G10*Assumptions!H15 -> 6837.9773 | H13: ='Income Statement'!H10*Assumptions!I15 -> 6826.4392 | I13: ='Income Statement'!I10*Assumptions!J15 -> 6819.8935
A14: Other current assets | C14: ='Historical Financials '!C30 -> 14695 | D14: ='Historical Financials '!D30 -> 14287 | E14: ='Income Statement'!E10*Assumptions!F16 -> 14582.584 | F14: ='Income Statement'!F10*Assumptions!G16 -> 14409.215 | G14: ='Income Statement'!G10*Assumptions!H16 -> 14430.566 | H14: ='Income Statement'!H10*Assumptions!I16 -> 14361.542 | I14: ='Income Statement'!I10*Assumptions!J16 -> 14288.567
A15: Total current assets | C15: ='Historical Financials '!C31 -> 143566 | D15: ='Historical Financials '!D31 -> 152987 | E15: =SUM(E9:E14) -> 148603.93 | F15: =SUM(F9:F14) -> 156823.42 | G15: =SUM(G9:G14) -> 159257.89 | H15: =SUM(H9:H14) -> 164923.03 | I15: =SUM(I9:I14) -> 170317.2
A17: Marketable securities - non-current | C17: ='Historical Financials '!C32 -> 100544 | D17: ='Historical Financials '!D32 -> 91479 | E17: =D17 -> 91479 | F17: =E17 -> 91479 | G17: =F17 -> 91479 | H17: =G17 -> 91479 | I17: =H17 -> 91479
A18: Property, plant and equipment, net | C18: ='Historical Financials '!C33 -> 43715 | D18: ='Historical Financials '!D33 -> 45680 | E18: =D18 -> 45680 | F18: =E18 -> 45680 | G18: =F18 -> 45680 | H18: =G18 -> 45680 | I18: =H18 -> 45680
A19: Other non-current assets | C19: ='Historical Financials '!C34 -> 64758 | D19: ='Historical Financials '!D34 -> 74834 | E19: =D19 -> 74834 | F19: =E19 -> 74834 | G19: =F19 -> 74834 | H19: =G19 -> 74834 | I19: =H19 -> 74834
A20: Total non-current assets | C20: ='Historical Financials '!C35 -> 209017 | D20: ='Historical Financials '!D35 -> 211993 | E20: =SUM(E17:E19) -> 211993 | F20: =SUM(F17:F19) -> 211993 | G20: =SUM(G17:G19) -> 211993 | H20: =SUM(H17:H19) -> 211993 | I20: =SUM(I17:I19) -> 211993
A21: Total assets | C21: ='Historical Financials '!C36 -> 352583 | D21: ='Historical Financials '!D36 -> 364980 | E21: =E15+E20 -> 360596.93 | F21: =F15+F20 -> 368816.42 | G21: =G15+G20 -> 371250.89 | H21: =H15+H20 -> 376916.03 | I21: =I15+I20 -> 382310.2
A23: Liabilities:
A24: Accounts payable | C24: ='Historical Financials '!C38 -> 62611 | D24: ='Historical Financials '!D38 -> 68960 | E24: ='Income Statement'!E15*Assumptions!F17 -> 66980.148 | F24: ='Income Statement'!F15*Assumptions!G17 -> 67990.385 | G24: ='Income Statement'!G15*Assumptions!H17 -> 66881.744 | H24: ='Income Statement'!H15*Assumptions!I17 -> 66761.537 | I24: ='Income Statement'!I15*Assumptions!J17 -> 66687.777
A25: Other current liabilities | C25: ='Historical Financials '!C39 -> 58829 | D25: ='Historical Financials '!D39 -> 78304 | E25: ='Income Statement'!E10*Assumptions!F18 -> 68892.061 | F25: ='Income Statement'!F10*Assumptions!G18 -> 71647.812 | G25: ='Income Statement'!G10*Assumptions!H18 -> 69360.847 | H25: ='Income Statement'!H10*Assumptions!I18 -> 69424.25 | I25: ='Income Statement'!I10*Assumptions!J18 -> 69596.803
A26: Deferred revenue | C26: ='Historical Financials '!C40 -> 8061 | D26: ='Historical Financials '!D40 -> 8249 | E26: ='Income Statement'!E10*Assumptions!F19 -> 8204.4373 | F26: ='Income Statement'!F10*Assumptions!G19 -> 8176.6384 | G26: ='Income Statement'!G10*Assumptions!H19 -> 8142.0659 | H26: ='Income Statement'!H10*Assumptions!I19 -> 8110.8302 | I26: ='Income Statement'!I10*Assumptions!J19 -> 8079.8657
A27: Commercial paper | C27: ='Historical Financials '!C41 -> 5985 | D27: ='Historical Financials '!D41 -> 9967 | E27: =D27 -> 9967 | F27: =E27 -> 9967 | G27: =F27 -> 9967 | H27: =G27 -> 9967 | I27: =H27 -> 9967
A28: Term debt - current | C28: ='Historical Financials '!C42 -> 9822 | D28: ='Historical Financials '!D42 -> 10912 | E28: =D28 -> 10912 | F28: =E28 -> 10912 | G28: =F28 -> 10912 | H28: =G28 -> 10912 | I28: =H28 -> 10912
A29: Total current liabilities | C29: ='Historical Financials '!C43 -> 145308 | D29: ='Historical Financials '!D43 -> 176392 | E29: =SUM(E24:E28) -> 164955.65 | F29: =SUM(F24:F28) -> 168693.83 | G29: =SUM(G24:G28) -> 165263.66 | H29: =SUM(H24:H28) -> 165175.62 | I29: =SUM(I24:I28) -> 165243.45
A31: Term debt - non-current | C31: ='Historical Financials '!C44 -> 95281 | D31: ='Historical Financials '!D44 -> 85750 | E31: =D31 -> 85750 | F31: =E31 -> 85750 | G31: =F31 -> 85750 | H31: =G31 -> 85750 | I31: =H31 -> 85750
A32: Other non-current liabilities | C32: ='Historical Financials '!C45 -> 49848 | D32: ='Historical Financials '!D45 -> 45888 | E32: =D32 -> 45888 | F32: =E32 -> 45888 | G32: =F32 -> 45888 | H32: =G32 -> 45888 | I32: =H32 -> 45888
A33: Total non-current liabilities | C33: ='Historical Financials '!C46 -> 145129 | D33: ='Historical Financials '!D46 -> 131638 | E33: =SUM(E31:E32) -> 131638 | F33: =SUM(F31:F32) -> 131638 | G33: =SUM(G31:G32) -> 131638 | H33: =SUM(H31:H32) -> 131638 | I33: =SUM(I31:I32) -> 131638
A34: Total liabilities | C34: ='Historical Financials '!C47 -> 290437 | D34: ='Historical Financials '!D47 -> 308030 | E34: =E29+E33 -> 296593.65 | F34: =F29+F33 -> 300331.83 | G34: =G29+G33 -> 296901.66 | H34: =H29+H33 -> 296813.62 | I34: =I29+I33 -> 296881.45
A36: Shareholders' equity:
A37: Common stock and additional paid-in capital | C37: ='Historical Financials '!C49 -> 73812 | D37: ='Historical Financials '!D49 -> 83276 | E37: =D37 -> 83276 | F37: =E37 -> 83276 | G37: =F37 -> 83276 | H37: =G37 -> 83276 | I37: =H37 -> 83276
A38: Accumulated deficit | C38: ='Historical Financials '!C50 -> -214 | D38: ='Historical Financials '!D50 -> -19154 | E38: =E40-E37-E39 -> -12100.714 | F38: =F40-F37-F39 -> -7619.4156 | G38: =G40-G37-G39 -> -1754.7708 | H38: =H40-H37-H39 -> 3998.4103 | I38: =I40-I37-I39 -> 9324.7573
A39: Accumulated other comprehensive loss | C39: ='Historical Financials '!C51 -> -11452 | D39: ='Historical Financials '!D51 -> -7172 | E39: =D39 -> -7172 | F39: =E39 -> -7172 | G39: =F39 -> -7172 | H39: =G39 -> -7172 | I39: =H39 -> -7172
A40: Total shareholders' equity | C40: ='Historical Financials '!C52 -> 62146 | D40: ='Historical Financials '!D52 -> 56950 | E40: =E21-E34 -> 64003.286 | F40: =F21-F34 -> 68484.584 | G40: =G21-G34 -> 74349.229 | H40: =H21-H34 -> 80102.41 | I40: =I21-I34 -> 85428.757
A41: Total liabilities and shareholders' equity | C41: ='Historical Financials '!C53 -> 352583 | D41: ='Historical Financials '!D53 -> 364980 | E41: =E34+E40 -> 360596.93 | F41: =F34+F40 -> 368816.42 | G41: =G34+G40 -> 371250.89 | H41: =H34+H40 -> 376916.03 | I41: =I34+I40 -> 382310.2

Sheet Cash Flow
A1: Apple Inc.
A2: Consolidated Statements of Cash Flows
A3: Fiscal Years 2022A–2029E
A4: USD in millions
B6: 2025E | C6: 2026E | D6: 2027E | E6: 2028E | F6: 2029E
A7: CASH FLOW
A8: Operating activities:
A9: Net income | B9: ='Income Statement'!E28 -> 96969.79 | C9: ='Income Statement'!F28 -> 96592.351 | D9: ='Income Statement'!G28 -> 96216.382 | E9: ='Income Statement'!H28 -> 95841.876 | F9: ='Income Statement'!I28 -> 95468.827
A10: Depreciation and amortization | B10: ='Income Statement'!E10*Assumptions!F22 -> 11488.323 | C10: ='Income Statement'!F10*Assumptions!G22 -> 11371.273 | D10: ='Income Statement'!G10*Assumptions!H22 -> 11332.058 | E10: ='Income Statement'!H10*Assumptions!I22 -> 11308.523 | F10: ='Income Statement'!I10*Assumptions!J22 -> 11249.175
A11: Share-based compensation | B11: ='Income Statement'!E10*Assumptions!F23 -> 11059.307 | C11: ='Income Statement'!F10*Assumptions!G23 -> 11032.956 | D11: ='Income Statement'!G10*Assumptions!H23 -> 10802.666 | E11: ='Income Statement'!H10*Assumptions!I23 -> 10879.508 | F11: ='Income Statement'!I10*Assumptions!J23 -> 10820.174
A12: Change in accounts receivable | B12: =-('Balance Sheet'!E11-'Balance Sheet'!D11) -> 1776.2851 | C12: =-('Balance Sheet'!F11-'Balance Sheet'!E11) -> -423.48257 | D12: =-('Balance Sheet'!G11-'Balance Sheet'!F11) -> 487.76654 | E12: =-('Balance Sheet'!H11-'Balance Sheet'!G11) -> 62.615982 | F12: =-('Balance Sheet'!I11-'Balance Sheet'!H11) -> 42.597432
A13: Change in inventories | B13: =-('Balance Sheet'!E13-'Balance Sheet'!D13) -> 440.24386 | C13: =-('Balance Sheet'!F13-'Balance Sheet'!E13) -> -110.11442 | D13: =-('Balance Sheet'!G13-'Balance Sheet'!F13) -> 117.89327 | E13: =-('Balance Sheet'!H13-'Balance Sheet'!G13) -> 11.538145 | F13: =-('Balance Sheet'!I13-'Balance Sheet'!H13) -> 6.5456383
A14: Change in other current assets | B14: =-('Balance Sheet'!E14-'Balance Sheet'!D14) -> -295.58396 | C14: =-('Balance Sheet'!F14-'Balance Sheet'!E14) -> 173.36918 | D14: =-('Balance Sheet'!G14-'Balance Sheet'!F14) -> -21.351239 | E14: =-('Balance Sheet'!H14-'Balance Sheet'!G14) -> 69.024438 | F14: =-('Balance Sheet'!I14-'Balance Sheet'!H14) -> 72.974346
A15: Change in accounts payable | B15: ='Balance Sheet'!E24-'Balance Sheet'!D24 -> -1979.8524 | C15: ='Balance Sheet'!F24-'Balance Sheet'!E24 -> 1010.2369 | D15: ='Balance Sheet'!G24-'Balance Sheet'!F24 -> -1108.6405 | E15: ='Balance Sheet'!H24-'Balance Sheet'!G24 -> -120.20694 | F15: ='Balance Sheet'!I24-'Balance Sheet'!H24 -> -73.759898
A16: Change in other current liabilities | B16: ='Balance Sheet'!E25-'Balance Sheet'!D25 -> -9411.9392 | C16: ='Balance Sheet'!F25-'Balance Sheet'!E25 -> 2755.7512 | D16: ='Balance Sheet'!G25-'Balance Sheet'!F25 -> -2286.965 | E16: ='Balance Sheet'!H25-'Balance Sheet'!G25 -> 63.403173 | F16: ='Balance Sheet'!I25-'Balance Sheet'!H25 -> 172.55244
A17: Change in deferred revenue | B17: ='Balance Sheet'!E26-'Balance Sheet'!D26 -> -44.56271 | C17: ='Balance Sheet'!F26-'Balance Sheet'!E26 -> -27.798935 | D17: ='Balance Sheet'!G26-'Balance Sheet'!F26 -> -34.572436 | E17: ='Balance Sheet'!H26-'Balance Sheet'!G26 -> -31.2357 | F17: ='Balance Sheet'!I26-'Balance Sheet'!H26 -> -30.964512
A18: Net cash provided by operating activities | B18: =SUM(B9:B17) -> 110002.01 | C18: =SUM(C9:C17) -> 122374.54 | D18: =SUM(D9:D17) -> 115505.24 | E18: =SUM(E9:E17) -> 118085.05 | F18: =SUM(F9:F17) -> 117728.12
A20: Investing activities:
A21: Capital expenditures | B21: =-'Income Statement'!E10*Assumptions!F24 -> -10307.383 | C21: =-'Income Statement'!F10*Assumptions!G24 -> -9991.7774 | D21: =-'Income Statement'!G10*Assumptions!H24 -> -10158.143 | E21: =-'Income Statement'!H10*Assumptions!I24 -> -10073.414 | F21: =-'Income Statement'!I10*Assumptions!J24 -> -9996.3269
A22: Net cash used in investing activities | B22: =B21 -> -10307.383 | C22: =C21 -> -9991.7774 | D22: =D21 -> -10158.143 | E22: =E21 -> -10073.414 | F22: =F21 -> -9996.3269
A24: Financing activities:
A25: Dividends paid | B25: =-'Income Statement'!E28*Assumptions!F25 -> -15282.478 | C25: =-'Income Statement'!F28*Assumptions!G25 -> -15309.782 | D25: =-'Income Statement'!G28*Assumptions!H25 -> -15121.217 | E25: =-'Income Statement'!H28*Assumptions!I25 -> -15119.303 | F25: =-'Income Statement'!I28*Assumptions!J25 -> -15065.297
A26: Share repurchases | B26: =-'Income Statement'!E10*Assumptions!F26 -> -86874.273 | C26: =-'Income Statement'!F10*Assumptions!G26 -> -89213.723 | D26: =-'Income Statement'!G10*Assumptions!H26 -> -87207.101 | E26: =-'Income Statement'!H10*Assumptions!I26 -> -87084.008 | F26: =-'Income Statement'!I10*Assumptions!J26 -> -87150.205
A27: Net cash used in financing activities | B27: =SUM(B25:B26) -> -102156.75 | C27: =SUM(C25:C26) -> -104523.5 | D27: =SUM(D25:D26) -> -102328.32 | E27: =SUM(E25:E26) -> -102203.31 | F27: =SUM(F25:F26) -> -102215.5
A29: Net increase / decrease in cash | B29: =B18+B22+B27 -> -2462.1233 | C29: =C18+C22+C27 -> 7859.2597 | D29: =D18+D22+D27 -> 3018.7754 | E29: =E18+E22+E27 -> 5808.3203 | F29: =F18+F22+F27 -> 5516.2924
A30: Cash at beginning of year | B30: ='Balance Sheet'!D9 -> 29943 | C30: =B31 -> 27480.877 | D30: =C31 -> 35340.136 | E30: =D31 -> 38358.912 | F30: =E31 -> 44167.232
A31: Cash at end of year | B31: =B30+B29 -> 27480.877 | C31: =C30+C29 -> 35340.136 | D31: =D30+D29 -> 38358.912 | E31: =E30+E29 -> 44167.232 | F31: =F30+F29 -> 49683.524

Sheet Checks
A1: Model Checks
A3: Check | B3: 2025E | C3: 2026E | D3: 2027E | E3: 2028E | F3: 2029E
A4: Total assets less liabilities & equity | B4: ='Balance Sheet'!E21-'Balance Sheet'!E41 -> 0 | C4: ='Balance Sheet'!F21-'Balance Sheet'!F41 -> 0 | D4: ='Balance Sheet'!G21-'Balance Sheet'!G41 -> 0 | E4: ='Balance Sheet'!H21-'Balance Sheet'!H41 -> 0 | F4: ='Balance Sheet'!I21-'Balance Sheet'!I41 -> 0
A5: Cash Flow ending cash less Balance Sheet cash | B5: ='Cash Flow'!B31-'Balance Sheet'!E9 -> 0 | C5: ='Cash Flow'!C31-'Balance Sheet'!F9 -> 0 | D5: ='Cash Flow'!D31-'Balance Sheet'!G9 -> 0 | E5: ='Cash Flow'!E31-'Balance Sheet'!H9 -> 0 | F5: ='Cash Flow'!F31-'Balance Sheet'!I9 -> 0
A6: Beginning cash equals prior ending cash | B6: =0 -> 0 | C6: ='Cash Flow'!C30-'Cash Flow'!B31 -> 0 | D6: ='Cash Flow'!D30-'Cash Flow'!C31 -> 0 | E6: ='Cash Flow'!E30-'Cash Flow'!D31 -> 0 | F6: ='Cash Flow'!F30-'Cash Flow'!E31 -> 0

Sheet Summary 
A1: Apple Inc.
A2: 3-Statement Financial Model Summary
A3: Fiscal Years 2025E–2029E
A4: USD in millions, except EPS
A6: Metric | B6: 2025E | C6: 2026E | D6: 2027E | E6: 2028E | F6: 2029E
A7: Revenue | B7: ='Income Statement'!E10 -> 389512.96 | C7: ='Income Statement'!F10 -> 387996.85 | D7: ='Income Statement'!G10 -> 386486.64 | E7: ='Income Statement'!H10 -> 384982.3 | F7: ='Income Statement'!I10 -> 383483.82
A8: Revenue growth % | B8: =Assumptions!F5 -> -0.0038923323 | C8: =Assumptions!G5 -> -0.0038923323 | D8: =Assumptions!H5 -> -0.0038923323 | E8: =Assumptions!I5 -> -0.0038923323 | F8: =Assumptions!J5 -> -0.0038923323
A9: Gross margin | B9: ='Income Statement'!E17 -> 173524.27 | C9: ='Income Statement'!F17 -> 172848.86 | D9: ='Income Statement'!G17 -> 172176.07 | E9: ='Income Statement'!H17 -> 171505.91 | F9: ='Income Statement'!I17 -> 170838.35
A10: Gross margin % | B10: ='Income Statement'!E17/'Income Statement'!E10 -> 0.44549037 | C10: ='Income Statement'!F17/'Income Statement'!F10 -> 0.44549037 | D10: ='Income Statement'!G17/'Income Statement'!G10 -> 0.44549037 | E10: ='Income Statement'!H17/'Income Statement'!H10 -> 0.44549037 | F10: ='Income Statement'!I17/'Income Statement'!I10 -> 0.44549037
A11: Operating income | B11: ='Income Statement'!E24 -> 118957.75 | C11: ='Income Statement'!F24 -> 118494.73 | D11: ='Income Statement'!G24 -> 118033.51 | E11: ='Income Statement'!H24 -> 117574.08 | F11: ='Income Statement'!I24 -> 117116.44
A12: Operating margin % | B12: ='Income Statement'!E24/'Income Statement'!E10 -> 0.30540127 | C12: ='Income Statement'!F24/'Income Statement'!F10 -> 0.30540127 | D12: ='Income Statement'!G24/'Income Statement'!G10 -> 0.30540127 | E12: ='Income Statement'!H24/'Income Statement'!H10 -> 0.30540127 | F12: ='Income Statement'!I24/'Income Statement'!I10 -> 0.30540127
A13: Net income | B13: ='Income Statement'!E28 -> 96969.79 | C13: ='Income Statement'!F28 -> 96592.351 | D13: ='Income Statement'!G28 -> 96216.382 | E13: ='Income Statement'!H28 -> 95841.876 | F13: ='Income Statement'!I28 -> 95468.827
A14: Net income margin % | B14: ='Income Statement'!E28/'Income Statement'!E10 -> 0.24895138 | C14: ='Income Statement'!F28/'Income Statement'!F10 -> 0.24895138 | D14: ='Income Statement'!G28/'Income Statement'!G10 -> 0.24895138 | E14: ='Income Statement'!H28/'Income Statement'!H10 -> 0.24895138 | F14: ='Income Statement'!I28/'Income Statement'!I10 -> 0.24895138
A15: Diluted EPS | B15: ='Income Statement'!E31 -> 6.2934315 | C15: ='Income Statement'!F31 -> 6.2689353 | D15: ='Income Statement'!G31 -> 6.2445346 | E15: ='Income Statement'!H31 -> 6.2202288 | F15: ='Income Statement'!I31 -> 6.1960176
A16: Ending cash | B16: ='Cash Flow'!B31 -> 27480.877 | C16: ='Cash Flow'!C31 -> 35340.136 | D16: ='Cash Flow'!D31 -> 38358.912 | E16: ='Cash Flow'!E31 -> 44167.232 | F16: ='Cash Flow'!F31 -> 49683.524
A17: Total assets | B17: ='Balance Sheet'!E21 -> 360596.93 | C17: ='Balance Sheet'!F21 -> 368816.42 | D17: ='Balance Sheet'!G21 -> 371250.89 | E17: ='Balance Sheet'!H21 -> 376916.03 | F17: ='Balance Sheet'!I21 -> 382310.2
A18: Total debt | B18: ='Balance Sheet'!E27+'Balance Sheet'!E28+'Balance Sheet'!E31 -> 106629 | C18: ='Balance Sheet'!F27+'Balance Sheet'!F28+'Balance Sheet'!F31 -> 106629 | D18: ='Balance Sheet'!G27+'Balance Sheet'!G28+'Balance Sheet'!G31 -> 106629 | E18: ='Balance Sheet'!H27+'Balance Sheet'!H28+'Balance Sheet'!H31 -> 106629 | F18: ='Balance Sheet'!I27+'Balance Sheet'!I28+'Balance Sheet'!I31 -> 106629
A19: Shareholders' equity | B19: ='Balance Sheet'!E40 -> 64003.286 | C19: ='Balance Sheet'!F40 -> 68484.584 | D19: ='Balance Sheet'!G40 -> 74349.229 | E19: ='Balance Sheet'!H40 -> 80102.41 | F19: ='Balance Sheet'!I40 -> 85428.757
